<?xml version="1.0"?>
<!-- Copyright (c) 2016 The UUV Simulator Authors.
     All rights reserved.

     Licensed under the Apache License, Version 2.0 (the "License");
     you may not use this file except in compliance with the License.
     You may obtain a copy of the License at

       http://www.apache.org/licenses/LICENSE-2.0

     Unless required by applicable law or agreed to in writing, software
     distributed under the License is distributed on an "AS IS" BASIS,
     WITHOUT WARRANTIES OR CONDITIONS OF ANY KIND, either express or implied.
     See the License for the specific language governing permissions and
     limitations under the License.
-->
<robot xmlns:xacro="http://www.ros.org/wiki/xacro">
    <!-- Import arm parameters -->
    <xacro:include filename="$(find predator_description)/urdf/parameters/serial_arm_predator.xacro" />
    <!-- Transmission Macro -->
    <xacro:macro name="simple_transmission" params="joint">
        <transmission name="${joint}_trans">
            <type>transmission_interface/SimpleTransmission</type>
            <joint name="${joint}">
                <hardwareInterface>hardware_interface/EffortJointInterface</hardwareInterface>
            </joint>
            <actuator name="${joint}_motor">
                <hardwareInterface>hardware_interface/EffortJointInterface</hardwareInterface>
                <mechanicalReduction>1</mechanicalReduction>
            </actuator>
        </transmission>
    </xacro:macro>


    <!-- Transmission Macro -->
    <!-- <xacro:macro name="simple_transmission" params="joint">
      <transmission name="${joint}_trans">
        <type>transmission_interface/SimpleTransmission</type>
        <joint name="${joint}">
          <hardwareInterface>EffortJointInterface</hardwareInterface>
        </joint>
        <actuator name="${joint}_motor">
          <hardwareInterface>EffortJointInterface</hardwareInterface>
          <mechanicalReduction>1</mechanicalReduction>
        </actuator>
      </transmission>
    </xacro:macro> -->



    <xacro:macro name="predator_serial_arm" params="namespace">

        <!-- Ground base -->

        <link name="${namespace}/base">
            <xacro:link_box_inertial mass="${total_mass * base_volume / total_volume_bbox}"
                        width="${base_width}"
                        length="${base_length}"
                        height="${base_height}">
            <origin xyz="${base_com}" rpy="0 0 0"/>
            </xacro:link_box_inertial>

            <visual>
                <origin xyz="0 0 0" rpy="0 0 0"/>
                <geometry>
                    <mesh filename="file://$(find predator_description)/meshes/base.dae"/>
                </geometry>
            </visual>

            <collision>
                <origin xyz="0 0 0" rpy="0 0 0"/>
                <geometry>
                    <mesh filename="file://$(find predator_description)/meshes/base.dae"/>
                </geometry>
            </collision>
        </link>

        <!-- Shoulder link -->

        <link name="${namespace}/shoulder_link">
            <xacro:link_box_inertial mass="${total_mass * shoulder_link_volume / total_volume_bbox}"
                        width="${shoulder_link_width}"
                        length="${shoulder_link_length}"
                        height="${predator_shoulder_height}">
                <origin xyz="${shoulder_link_com}" rpy="0 0 0"/>
            </xacro:link_box_inertial>

            <visual>
                <origin xyz="0 0 0" rpy="0 0 1.57079632679"/>
                <geometry>
                    <mesh filename="file://$(find predator_description)/meshes/shoulder.dae"/>
                </geometry>
            </visual>

            <collision>
                <origin xyz="0 0 0" rpy="0 0 1.57079632679"/>
                <geometry>
                    <mesh filename="file://$(find predator_description)/meshes/shoulder.dae"/>
                </geometry>                
            </collision>
        </link>

        <joint name="${namespace}/azimuth" type="revolute">
            <origin xyz="0 0 0" rpy="0 0 0"/>
            <parent link="${namespace}/base"/>
            <child link="${namespace}/shoulder_link"/>
            <axis xyz="0 0 1"/>
            <origin xyz="0 0 0.0003" rpy="0 0 0"/>
            <dynamics damping="100" friction="150"/>
            <limit lower="${-60 * d2r}" upper="${60 * d2r}" velocity="0.17" effort="200"/>
        </joint>

        <xacro:simple_transmission joint="${namespace}/azimuth" />

        <!-- UPPER ARM -->

        <link name="${namespace}/upper_arm">
            <xacro:link_box_inertial mass="${total_mass * upper_arm_volume / total_volume_bbox}"
                        width="${upper_arm_width}"
                        length="${upper_arm_length}"
                        height="${upper_arm_height}">
                <origin xyz="${upper_arm_com}" rpy="0 0 0"/>
            </xacro:link_box_inertial>

            <visual>
                <origin xyz="0 0 0" rpy="0 ${0.5*pi} 0"/>
                <geometry>
                    <mesh filename="file://$(find predator_description)/meshes/upperarm.dae"/>
                </geometry>
            </visual>

            <collision>
                <origin xyz="0 0 0" rpy="0 ${0.5*pi} 0"/>
                <geometry>
                    <mesh filename="file://$(find predator_description)/meshes/upperarm.dae"/>
                </geometry>
            </collision>
        </link>

        <joint name="${namespace}/shoulder" type="revolute">
            <parent link="${namespace}/shoulder_link"/>
            <child link="${namespace}/upper_arm"/>
            <origin xyz="0.200369 0 0.209467" rpy="${0.5*pi} 0 0"/>
            <axis xyz="0 0 1"/>
            <dynamics damping="50" friction="150"/>
            <limit lower="${-90 * d2r}" upper="${90 * d2r}" velocity=".17" effort="5000"/>
        </joint>

        <xacro:simple_transmission joint="${namespace}/shoulder" />

        <!-- FOREARM -->

        <link name="${namespace}/forearm">
            <xacro:link_box_inertial mass="${total_mass * elbow_link_volume / total_volume_bbox}"
                        width="${elbow_link_width}"
                        length="${elbow_link_length}"
                        height="${predator_elbow_length}">
                <origin xyz="${elbow_link_com}" rpy="0 0 0"/>
            </xacro:link_box_inertial>

            <visual>
                <origin xyz="0 0 0" rpy="0 ${0.5*pi} ${0.5*pi}"/>
                <geometry>
                    <mesh filename="file://$(find predator_description)/meshes/forearm.dae"/>
                </geometry>
            </visual>

            <collision>
                <origin xyz="0 0 0" rpy="0 ${0.5*pi} ${0.5*pi}"/>
                <geometry>
                    <mesh filename="file://$(find predator_description)/meshes/forearm.dae"/>
                </geometry>
            </collision>
        </link>

        <joint name="${namespace}/elbow" type="revolute">
            <parent link="${namespace}/upper_arm"/>
            <child link="${namespace}/forearm"/>
            <origin xyz="0.87315 0 0" rpy="0 0 0"/>
            <dynamics damping="50" friction="150"/>
            <axis xyz="0 0 1"/>
            <limit lower="${-90 * d2r}" upper="${60 * d2r}" velocity=".15" effort="300"/>
        </joint>

        <xacro:simple_transmission joint="${namespace}/elbow" />

        <!-- WRIST -->

        <link name="${namespace}/wrist">
            <xacro:link_box_inertial mass="${total_mass * forearm_volume / total_volume_bbox}"
                        width="${forearm_width}"
                        length="${forearm_length}"
                        height="${forearm_height}">
                <origin xyz="${forearm_com}" rpy="0 0 0"/>
            </xacro:link_box_inertial>

            <visual>
                <origin xyz="0 0 0" rpy="1.57079632679 1.57079632679 -1.57079632679"/>
                <geometry>
                    <mesh filename="file://$(find predator_description)/meshes/wrist.dae"/>
                </geometry>
            </visual>

            <collision>
                <origin xyz="0 0 0" rpy="1.57079632679 1.57079632679 -1.57079632679"/>
                <geometry>
                    <mesh filename="file://$(find predator_description)/meshes/wrist.dae"/>
                </geometry>
            </collision>
        </link>

        <joint name="${namespace}/pitch" type="revolute">
            <parent link="${namespace}/forearm"/>
            <child link="${namespace}/wrist"/>
            <origin xyz="0.11275 -0.55503 0" rpy="0 0 -1.57079632679"/>
            <axis xyz="0 0 1"/>
            <dynamics damping="30" friction="50"/>
            <limit lower="${-135 * d2r}" upper="${135 * d2r}" velocity=".25" effort="1000"/>
        </joint>

        <xacro:simple_transmission joint="${namespace}/pitch" />

        <!-- Adding parallel gripper  -->
        <xacro:include filename="$(find predator_description)/urdf/parallel_gripper_predator.xacro" />
        
        <xacro:oberon7_gazebo_macro namespace="${namespace}"/>
    </xacro:macro>
</robot>
