<?xml version="1.0"?>
<sdf version="1.6">
  <model name="glider_slocum">
    <static>false</static>
    <link name="base_link">
      <visual name="visual">
        <pose>0 0 1 0 0 0</pose>
        <geometry>
          <mesh>
            <scale>1.0 1.0 1.0</scale>
            <uri>model://glider_slocum/mesh/Slocum-Glider.dae</uri>
          </mesh>
        </geometry>
      </visual>
      <collision name="collision">
        <pose>0 0 1 0 0 0</pose>
        <geometry>
          <mesh>
            <scale>1.0 1.0 1.0</scale>
            <uri>model://glider_slocum/mesh/COLLISION-Slocum-Glider.dae</uri>
          </mesh>
        </geometry>
      </collision>
      <inertial>
          <pose>0 0 1 0 0 0</pose>
          <inertia>
              <ixx>10</ixx>
              <ixy>0</ixy>
              <ixz>0</ixz>
              <iyy>10</iyy>
              <iyz>0</iyz>
              <izz>10</izz>
          </inertia>
          <mass>100.0</mass>
      </inertial>
    </link>
    <link name="propeller_link">
      <visual name="visual">
        <pose>0 0 1 0 0 0</pose>
        <geometry>
          <mesh>
            <scale>1.0 1.0 1.0</scale>
            <uri>model://glider_slocum/mesh/Slocum-Glider-Propeller.dae</uri>
          </mesh>
        </geometry>
      </visual>
      <inertial>
          <pose>0 0 1 0 0 0</pose>
          <inertia>
              <ixx>0.1</ixx>
              <ixy>0</ixy>
              <ixz>0</ixz>
              <iyy>0.1</iyy>
              <iyz>0</iyz>
              <izz>0.1</izz>
          </inertia>
          <mass>0.5</mass>
      </inertial>
    </link>
    <joint name="propeller_joint" type="revolute">
        <pose>0 0 1 0 0 0</pose>
        <parent>base_link</parent>
        <child>propeller_link</child>
        <axis>
            <xyz>0 1 0</xyz>
        </axis>
    </joint>
  </model>
</sdf>