<?xml version="1.0" ?>
<sdf version="1.4">
  <world name="default">
    <include>
      <uri>model://ground_plane</uri>
    </include>

    <include>
      <uri>model://sun</uri>
    </include>
    
  <model name="my_system">>
    <include>
      <uri>model://electrical_plug</uri>
      <pose>2 0 2 0 0 0</pose>
    </include>
    <include>
      <uri>model://electrical_socket</uri>
      <pose>-2 0 2 0 0 0</pose>
    </include>


    <!-- reference to your plugin -->
    <!-- <plugin name="hello_uuv_plutin" filename="libuuv_world_plugin.so"/> -->
    <joint name="joint_00" type="revolute">
      <!-- <parent>elecs</parent>
      <child>elecp</child> -->
      <pose>0.0 0.0 0.0 0.0 0.0 0.0</pose>
      <parent>electrical_socket::elecs</parent>
      <child>electrical_plug::elecp</child>
      <axis>
        <xyz>1.0 0.0 0.0</xyz>
      </axis>
    </joint>
  </model>
  
  
  </world>
</sdf>
