<?xml version='1.0'?>
<sdf version ='1.6'>

  <model name ='electrical_plug_socket_system'>
    <pose>0 0 0 0 0 0</pose>
    <link name ='plug'>
      <pose>-1 0 0 0 0 0</pose>

      <inertial>
        <mass>1</mass>
      </inertial>

      <collision name ='collision'>
        <laser_retro>255</laser_retro>
        <geometry>
          <box><size>0.5 0.5 0.5</size></box>
        </geometry>
      </collision>
      <visual name ='visual'>
        <geometry>
          <box><size>0.5 0.5 0.5</size></box>
        </geometry>
      </visual>
    </link>

    <model name="socket">
      <pose>1.0 0 0.0 0 0 0</pose>
      <link name ='socket'>
        <pose>0 0 0 0 0 0</pose>
        <collision name ='collision'>
          <laser_retro>255</laser_retro>
          <geometry>
            <box><size>0.5 0.5 0.5</size></box>
          </geometry>
        </collision>
        <visual name ='visual'>
          <geometry>
            <box><size>0.5 0.5 0.5</size></box>
          </geometry>
        </visual>
      </link>
    </model>

    <joint name="electrical_joint" type="prismatic">
      <parent>plug</parent>
      <child>socket::socket</child>
      <pose>0.0 0.0 0.0 0.0 0.0 0.0</pose>
      <axis>
        <xyz>1.0 0.0 0.0</xyz>
      </axis>
    </joint>

    

  </model>
</sdf>
