<?xml version="1.0"?>
<sdf version="1.6">
  <model name="glider_hybrid_whoi">
    <static>false</static>
    <link name="base_link">
      <visual name="visual">
        <pose>0 0 0 0 0 0</pose>
        <geometry>
          <mesh>
            <scale>1.0 1.0 1.0</scale>
            <uri>model://glider_hybrid_whoi/mesh/glider_hybrid_whoi_body.dae</uri>
          </mesh>
        </geometry>
      </visual>
      <collision name="collision">
        <pose>0 0 0 0 0 0</pose>
        <geometry>
          <mesh>
            <scale>1.0 1.0 1.0</scale>
            <uri>model://glider_hybrid_whoi/mesh/glider_hybrid_whoi_collision.dae</uri>
          </mesh>
        </geometry>
      </collision>
      <inertial>
          <pose>0 0 0 0 0 0</pose>
          <inertia>
              <ixx>10</ixx>
              <ixy>0</ixy>
              <ixz>0</ixz>
              <iyy>10</iyy>
              <iyz>0</iyz>
              <izz>10</izz>
          </inertia>
          <mass>50</mass>
      </inertial>
    </link>
    <link name="right_propeller_link">
      <visual name="visual">
        <pose>0 0 0 0 0 0</pose>
        <geometry>
          <mesh>
            <scale>1.0 1.0 1.0</scale>
            <uri>model://glider_hybrid_whoi/mesh/glider_hybrid_whoi_right_propeller.dae</uri>
          </mesh>
        </geometry>
      </visual>
      <inertial>
          <pose>0 0 0 0 0 0</pose>
          <inertia>
              <ixx>0.1</ixx>
              <ixy>0</ixy>
              <ixz>0</ixz>
              <iyy>0.1</iyy>
              <iyz>0</iyz>
              <izz>0.1</izz>
          </inertia>
          <mass>0.5</mass>
      </inertial>
    </link>
    <link name="left_propeller_link">
      <visual name="visual">
        <pose>0 0 0 0 0 0</pose>
        <geometry>
          <mesh>
            <scale>1.0 1.0 1.0</scale>
            <uri>model://glider_hybrid_whoi/mesh/glider_hybrid_whoi_left_propeller.dae</uri>
          </mesh>
        </geometry>
      </visual>
      <inertial>
          <pose>0 0 0 0 0 0</pose>
          <inertia>
              <ixx>0.1</ixx>
              <ixy>0</ixy>
              <ixz>0</ixz>
              <iyy>0.1</iyy>
              <iyz>0</iyz>
              <izz>0.1</izz>
          </inertia>
          <mass>0.5</mass>
      </inertial>
    </link>
    <joint name="right_propeller_joint" type="revolute">
        <pose>0.0535 -0.55 0 0 0 -0.20</pose>
        <child>right_propeller_link</child>
        <parent>base_link</parent>
        <axis>
            <xyz>0 1 0</xyz>
        </axis>
    </joint>
    <joint name="left_propeller_joint" type="revolute">
        <pose>-0.0535 -0.55 0 0 0 0.20</pose>
        <child>left_propeller_link</child>
        <parent>base_link</parent>
        <axis>
            <xyz>0 1 0</xyz>
        </axis>
    </joint>
  </model>
</sdf>
